<?xml version="1.0" ?>
<robot name="i214" xmlns:xacro="http://www.ros.org/wiki/xacro">
  <xacro:include filename="$(find i214_description)/urdf/materials.xacro" />
  <xacro:include filename="$(find i214_description)/urdf/i214.gazebo" />
  <xacro:include filename="$(find i214_description)/urdf/macros.xacro" />

  <link name="link_chassis">
    <!-- pose and inertial -->
    <pose>0 0 0.1 0 0 0</pose>
    <inertial>
      <mass value="5"/>
      <origin rpy="0 0 0" xyz="0 0 0.1"/>
      <inertia ixx="0.0395416666667" ixy="0" ixz="0" iyy="0.106208333333" iyz="0" izz="0.106208333333"/>
    </inertial>
    <!-- body -->
    <collision name="collision_chassis">
      <geometry>
        <box size="0.5 0.3 0.07"/>
      </geometry>
    </collision>
    <visual>
      <origin rpy="0 0 0" xyz="0 0 0"/>
      <geometry>
        <box size="0.5 0.3 0.07"/>
      </geometry>
      <material name="blue"/>
    </visual>
    <!-- camera mount -->
    <collision name="collision_camera_mount">
      <geometry>
        <box size="0.1 0.25 0.1"/>
      </geometry>
    </collision>
    <visual>
      <origin rpy="0 0 0" xyz="0 0 0.05"/>
      <geometry>
        <box size="0.1 0.25 0.1"/>
      </geometry>
      <material name="blue"/>
    </visual>
    <!-- caster front -->
    <collision name="caster_front_collision">
      <origin rpy=" 0 0 0" xyz="0.35 0 -0.05"/>
      <geometry>
        <sphere radius="0.05"/>
      </geometry>
      <surface>
        <friction>
          <ode>
            <mu>0</mu>
            <mu2>0</mu2>
            <slip1>1.0</slip1>
            <slip2>1.0</slip2>
          </ode>
        </friction>
      </surface>
    </collision>
    <visual name="caster_front_visual">
      <origin rpy=" 0 0 0" xyz="0.2 0 -0.05"/>
      <geometry>
        <sphere radius="0.05"/>
      </geometry>
    </visual>
  </link>

  <joint name="camera_joint" type="fixed">
    <axis xyz="0 1 0" />
    <origin xyz="0 0 0.15" rpy="0 0 0"/>
    <parent link="link_chassis"/>
    <child link="camera_link"/>
  </joint>

  <!-- Camera -->
  <link name="camera_link">
    <collision>
      <origin xyz="0 0 0" rpy="0 0 0"/>
      <geometry>
        <box size="0.1 0.1 0.1"/>
      </geometry>
    </collision>

    <visual>
      <origin xyz="0 0 0" rpy="0 0 0"/>
      <geometry>
        <box size="0.1 0.1 0.1"/>
      </geometry>
      <material name="red"/>
    </visual>

    <inertial>
      <mass value="1e-5" />
      <origin xyz="0 0 0" rpy="0 0 0"/>
      <inertia ixx="1e-6" ixy="0" ixz="0" iyy="1e-6" iyz="0" izz="1e-6" />
    </inertial>
  </link>

  <link name="sensor_laser">
  <inertial>
      <origin xyz="0 0 0" rpy="0 0 0" />
      <mass value="0.1" />
      <xacro:cylinder_inertia m="0.1" r="0.05" h="0.1" />
  </inertial>

  <visual>
      <origin xyz="0 0 0" rpy="0 0 0" />
      <geometry>
      <cylinder radius="0.05" length="0.1"/>
      </geometry>
      <material name="white" />
  </visual>

  <collision>
      <origin xyz="0 0 0" rpy="0 0 0"/>
      <geometry>
      <cylinder radius="0.05" length="0.1"/>
      </geometry>
  </collision>
  </link>

  <joint name="joint_sensor_laser" type="fixed">
      <origin xyz="0.15 0 0.05" rpy="0 0 0"/>
      <parent link="link_chassis"/>
      <child link="sensor_laser"/>
  </joint>

  <joint name="imu_joint" type="fixed">
   <axis xyz="1 0 0"/> <!-- 0 1 0 -->
   <origin xyz="-0.15 0 0.05"/>
   <parent link="link_chassis"/>
   <child link="imu_link"/>
 </joint>


 <link name="imu_link">
  <inertial>
    <mass value="0.001"/>
    <origin rpy="0 0 0" xyz="0 0 0"/>
    <inertia ixx="0.0001" ixy="0" ixz="0" iyy="0.000001" iyz="0" izz="0.0001"/>
  </inertial>
  <visual>
    <origin rpy="0 0 0" xyz="0 0 0"/>
    <geometry>
      <box size="0.15 0.1 0.02"/>
    </geometry>
    <material name="white" />
  </visual>
  <collision>
    <origin rpy="0 0 0" xyz="0 0 0"/>
    <geometry>
      <box size=".15 .1 .02"/>
    </geometry>
  </collision>
 </link>

 <link name="left_wheel">
   <!--origin xyz="0.1 0.13 0.1" rpy="0 1.5707 1.5707"/-->
   <collision name="collision">
     <origin xyz="0 0 0" rpy="0 1.5707 1.5707"/>
     <geometry>
       <cylinder radius="0.1" length="0.05"/>
     </geometry>
   </collision>
   <visual name="left_wheel_visual">
     <origin xyz="0 0 0" rpy="0 1.5707 1.5707"/>
     <geometry>
       <cylinder radius="0.1" length="0.05"/>
     </geometry>
   </visual>
   <inertial>
     <origin xyz="0 0 0" rpy="0 1.5707 1.5707"/>
     <mass value="5"/>
     <cylinder_inertia m="5" r="0.1" h="0.05"/>
     <inertia
       ixx="1.0" ixy="0.0" ixz="0.0"
       iyy="1.0" iyz="0.0"
       izz="1.0"/>
   </inertial>
 </link>

 <link name="right_wheel">
   <!--origin xyz="0.1 -0.13 0.1" rpy="0 1.5707 1.5707"/-->
   <collision name="collision">
     <origin xyz="0 0 0" rpy="0 1.5707 1.5707"/>
     <geometry>
       <cylinder radius="0.1" length="0.05"/>
     </geometry>
   </collision>
   <visual name="right_wheel_visual">
     <origin xyz="0 0 0" rpy="0 1.5707 1.5707"/>
     <geometry>
       <cylinder radius="0.1" length="0.05"/>
     </geometry>
   </visual>
   <inertial>
     <origin xyz="0 0 0" rpy="0 1.5707 1.5707"/>
     <mass value="5"/>
     <cylinder_inertia m="5" r="0.1" h="0.05"/>
     <inertia
       ixx="1.0" ixy="0.0" ixz="0.0"
       iyy="1.0" iyz="0.0"
       izz="1.0"/>
   </inertial>
 </link>


 <joint type="continuous" name="left_wheel_hinge">
   <origin xyz="-0.1 0.15 0" rpy="0 0 0"/>
   <child link="left_wheel"/>
   <parent link="link_chassis"/>
   <axis xyz="0 1 0" rpy="0 0 0"/>
   <limit effort="100" velocity="100"/>
   <joint_properties damping="0.0" friction="0.0"/>
 </joint>

 <joint type="continuous" name="right_wheel_hinge">
   <origin xyz="-0.1 -0.15 0" rpy="0 0 0"/>
   <child link="right_wheel"/>
   <parent link="link_chassis"/>
   <axis xyz="0 1 0" rpy="0 0 0"/>
   <limit effort="100" velocity="100"/>
   <joint_properties damping="0.0" friction="0.0"/>
 </joint>

</robot>
